Workbook

Sheet Order_level_Calculation
A1: Order ID | B1: AWB Number | C1: Total Weight as per X (KG) | D1: Weight Slab as per X (KG) | E1: Fixed_Weight | F1: Additional_Weight | G1: Total Weight as per courier Company (KG) | H1: Weight slab charged by Courier Company (KG) | I1: Delivery Zone as per X | J1: Type of Shipment | K1: Comp_Key | L1: Delivery Zone charged by Courier Company | M1: Expected Charge as per X (Rs) | N1: Charges Billed by Courier Company (Rs.) | O1: Difference Between Expected Charges and Billed Charges(Rs.)
A2: 2001806232 | B2: 1091117222124 | C2: =SUMIF('Company X - order Report'!$A:$A,A2,'Company X - order Report'!$E:$E) -> 1.302 | D2: =CEILING(C2,0.5) -> 1.5 | E2: =1 -> 1 | F2: =(D2-0.5)/0.5 -> 2 | G2: =VLOOKUP(A2,Courier_compnay_invoice!B:C,2,0) -> 1.3 | H2: =CEILING(G2,0.5) -> 1.5 | I2: =VLOOKUP(A2,'Company X - Pincode Zones'!A:D,4,0) -> d | J2: =VLOOKUP(I2,'Company X - Pincode Zones'!D:E,2,0) -> Forward charges | K2: =IF(AND(I2="a",J2="Forward charges"),"fwd_a",IF(AND(I2="b",J2="Forward charges"),"fwd_b",IF(AND(I2="c",J2="Forward charge"),"fwd_c",IF(AND(I2="d",J2="Forward charge"),"fwd_d",IF(AND(I2="e",J2="Forward chrage"),"fwd_e",))))) | L2: =VLOOKUP(A2,Courier_compnay_invoice!B:F,5,0) -> d | M2: =IFS(I2="a",(Curioer_Rate!$B$5+((D2-0.5)*2)*Curioer_Rate!$C$5), I2 ="b",(Curioer_Rate!$B$6+((D2-0.5)*2)*Curioer_Rate!$C$6), I2="c",(Curioer_Rate!$B$7+((D2-0.5)*2)*Curioer_Rate!$C$7), I2="d",(Curioer_Rate!$B$8+((D2-0.5)*2)*Curioer_Rate!$C$8), I2="e",(Curioer_Rate!$B$9+((D2-0.5)*2)*Curioer_Rate!$C$9)) -> 135 | N2: =VLOOKUP(A2,Courier_compnay_invoice!B:H,7,0) -> 135 | O2: =M2-N2 -> 0
A3: 2001806273 | B3: 1091117222194 | C3: =SUMIF('Company X - order Report'!$A:$A,A3,'Company X - order Report'!$E:$E) -> 0.615 | D3: =CEILING(C3,0.5) -> 1 | E3: =1 -> 1 | F3: =(D3-0.5)/0.5 -> 1 | G3: =VLOOKUP(A3,Courier_compnay_invoice!B:C,2,0) -> 1 | H3: =CEILING(G3,0.5) -> 1 | I3: =VLOOKUP(A3,'Company X - Pincode Zones'!A:D,4,0) -> d | J3: =VLOOKUP(I3,'Company X - Pincode Zones'!D:E,2,0) -> Forward charges | K3: =IF(AND(I3="d",J3="Forward charges"),"fwd_d","NA") -> fwd_d | L3: =VLOOKUP(A3,Courier_compnay_invoice!B:F,5,0) -> d | M3: =IFS(I3="a",(Curioer_Rate!$B$5+((D3-0.5)*2)*Curioer_Rate!$C$5), I3 ="b",(Curioer_Rate!$B$6+((D3-0.5)*2)*Curioer_Rate!$C$6), I3="c",(Curioer_Rate!$B$7+((D3-0.5)*2)*Curioer_Rate!$C$7), I3="d",(Curioer_Rate!$B$8+((D3-0.5)*2)*Curioer_Rate!$C$8), I3="e",(Curioer_Rate!$B$9+((D3-0.5)*2)*Curioer_Rate!$C$9)) -> 90.2 | N3: =VLOOKUP(A3,Courier_compnay_invoice!B:H,7,0) -> 90.2 | O3: =M3-N3 -> 0
A4: 2001806408 | B4: 1091117222931 | C4: =SUMIF('Company X - order Report'!$A:$A,A4,'Company X - order Report'!$E:$E) -> 2.265 | D4: =CEILING(C4,0.5) -> 2.5 | E4: =1 -> 1 | F4: =(D4-0.5)/0.5 -> 4 | G4: =VLOOKUP(A4,Courier_compnay_invoice!B:C,2,0) -> 2.5 | H4: =CEILING(G4,0.5) -> 2.5 | I4: =VLOOKUP(A4,'Company X - Pincode Zones'!A:D,4,0) -> d | J4: =VLOOKUP(I4,'Company X - Pincode Zones'!D:E,2,0) -> Forward charges | K4: =IF(AND(I4="d",J4="Forward charges"),"fwd_d","NA") -> fwd_d | L4: =VLOOKUP(A4,Courier_compnay_invoice!B:F,5,0) -> d | M4: =IFS(I4="a",(Curioer_Rate!$B$5+((D4-0.5)*2)*Curioer_Rate!$C$5), I4 ="b",(Curioer_Rate!$B$6+((D4-0.5)*2)*Curioer_Rate!$C$6), I4="c",(Curioer_Rate!$B$7+((D4-0.5)*2)*Curioer_Rate!$C$7), I4="d",(Curioer_Rate!$B$8+((D4-0.5)*2)*Curioer_Rate!$C$8), I4="e",(Curioer_Rate!$B$9+((D4-0.5)*2)*Curioer_Rate!$C$9)) -> 224.6 | N4: =VLOOKUP(A4,Courier_compnay_invoice!B:H,7,0) -> 224.6 | O4: =M4-N4 -> 0
A5: 2001806458 | B5: 1091117223244 | C5: =SUMIF('Company X - order Report'!$A:$A,A5,'Company X - order Report'!$E:$E) -> 0.7 | D5: =CEILING(C5,0.5) -> 1 | E5: =1 -> 1 | F5: =(D5-0.5)/0.5 -> 1 | G5: =VLOOKUP(A5,Courier_compnay_invoice!B:C,2,0) -> 1 | H5: =CEILING(G5,0.5) -> 1 | I5: =VLOOKUP(A5,'Company X - Pincode Zones'!A:D,4,0) -> b | J5: =VLOOKUP(I5,'Company X - Pincode Zones'!D:E,2,0) -> Forward charges | K5: =IF(AND(I5="d",J5="Forward charges"),"fwd_d","NA") -> NA | L5: =VLOOKUP(A5,Courier_compnay_invoice!B:F,5,0) -> b | M5: =IFS(I5="a",(Curioer_Rate!$B$5+((D5-0.5)*2)*Curioer_Rate!$C$5), I5 ="b",(Curioer_Rate!$B$6+((D5-0.5)*2)*Curioer_Rate!$C$6), I5="c",(Curioer_Rate!$B$7+((D5-0.5)*2)*Curioer_Rate!$C$7), I5="d",(Curioer_Rate!$B$8+((D5-0.5)*2)*Curioer_Rate!$C$8), I5="e",(Curioer_Rate!$B$9+((D5-0.5)*2)*Curioer_Rate!$C$9)) -> 61.3 | N5: =VLOOKUP(A5,Courier_compnay_invoice!B:H,7,0) -> 61.3 | O5: =M5-N5 -> 0
A6: 2001807012 | B6: 1091117229345 | C6: =SUMIF('Company X - order Report'!$A:$A,A6,'Company X - order Report'!$E:$E) -> 0.24 | D6: =CEILING(C6,0.5) -> 0.5 | E6: =1 -> 1 | F6: =(D6-0.5)/0.5 -> 0 | G6: =VLOOKUP(A6,Courier_compnay_invoice!B:C,2,0) -> 0.15 | H6: =CEILING(G6,0.5) -> 0.5 | I6: =VLOOKUP(A6,'Company X - Pincode Zones'!A:D,4,0) -> d | J6: =VLOOKUP(I6,'Company X - Pincode Zones'!D:E,2,0) -> Forward charges | K6: =IF(AND(I6="d",J6="Forward charges"),"fwd_d","NA") -> fwd_d | L6: =VLOOKUP(A6,Courier_compnay_invoice!B:F,5,0) -> d | M6: =IFS(I6="a",(Curioer_Rate!$B$5+((D6-0.5)*2)*Curioer_Rate!$C$5), I6 ="b",(Curioer_Rate!$B$6+((D6-0.5)*2)*Curioer_Rate!$C$6), I6="c",(Curioer_Rate!$B$7+((D6-0.5)*2)*Curioer_Rate!$C$7), I6="d",(Curioer_Rate!$B$8+((D6-0.5)*2)*Curioer_Rate!$C$8), I6="e",(Curioer_Rate!$B$9+((D6-0.5)*2)*Curioer_Rate!$C$9)) -> 45.4 | N6: =VLOOKUP(A6,Courier_compnay_invoice!B:H,7,0) -> 45.4 | O6: =M6-N6 -> 0
A7: 2001806686 | B7: 1091117229555 | C7: =SUMIF('Company X - order Report'!$A:$A,A7,'Company X - order Report'!$E:$E) -> 0.24 | D7: =CEILING(C7,0.5) -> 0.5 | E7: =1 -> 1 | F7: =(D7-0.5)/0.5 -> 0 | G7: =VLOOKUP(A7,Courier_compnay_invoice!B:C,2,0) -> 0.15 | H7: =CEILING(G7,0.5) -> 0.5 | I7: =VLOOKUP(A7,'Company X - Pincode Zones'!A:D,4,0) -> d | J7: =VLOOKUP(I7,'Company X - Pincode Zones'!D:E,2,0) -> Forward charges | K7: =IF(AND(I7="d",J7="Forward charges"),"fwd_d","NA") -> fwd_d | L7: =VLOOKUP(A7,Courier_compnay_invoice!B:F,5,0) -> d | M7: =IFS(I7="a",(Curioer_Rate!$B$5+((D7-0.5)*2)*Curioer_Rate!$C$5), I7 ="b",(Curioer_Rate!$B$6+((D7-0.5)*2)*Curioer_Rate!$C$6), I7="c",(Curioer_Rate!$B$7+((D7-0.5)*2)*Curioer_Rate!$C$7), I7="d",(Curioer_Rate!$B$8+((D7-0.5)*2)*Curioer_Rate!$C$8), I7="e",(Curioer_Rate!$B$9+((D7-0.5)*2)*Curioer_Rate!$C$9)) -> 45.4 | N7: =VLOOKUP(A7,Courier_compnay_invoice!B:H,7,0) -> 45.4 | O7: =M7-N7 -> 0
A8: 2001806885 | B8: 1091117229776 | C8: =SUMIF('Company X - order Report'!$A:$A,A8,'Company X - order Report'!$E:$E) -> 0.84 | D8: =CEILING(C8,0.5) -> 1 | E8: =1 -> 1 | F8: =(D8-0.5)/0.5 -> 1 | G8: =VLOOKUP(A8,Courier_compnay_invoice!B:C,2,0) -> 1 | H8: =CEILING(G8,0.5) -> 1 | I8: =VLOOKUP(A8,'Company X - Pincode Zones'!A:D,4,0) -> b | J8: =VLOOKUP(I8,'Company X - Pincode Zones'!D:E,2,0) -> Forward charges | K8: =IF(AND(I8="d",J8="Forward charges"),"fwd_d","NA") -> NA | L8: =VLOOKUP(A8,Courier_compnay_invoice!B:F,5,0) -> b | M8: =IFS(I8="a",(Curioer_Rate!$B$5+((D8-0.5)*2)*Curioer_Rate!$C$5), I8 ="b",(Curioer_Rate!$B$6+((D8-0.5)*2)*Curioer_Rate!$C$6), I8="c",(Curioer_Rate!$B$7+((D8-0.5)*2)*Curioer_Rate!$C$7), I8="d",(Curioer_Rate!$B$8+((D8-0.5)*2)*Curioer_Rate!$C$8), I8="e",(Curioer_Rate!$B$9+((D8-0.5)*2)*Curioer_Rate!$C$9)) -> 61.3 | N8: =VLOOKUP(A8,Courier_compnay_invoice!B:H,7,0) -> 61.3 | O8: =M8-N8 -> 0
A9: 2001807058 | B9: 1091117323112 | C9: =SUMIF('Company X - order Report'!$A:$A,A9,'Company X - order Report'!$E:$E) -> 1.168 | D9: =CEILING(C9,0.5) -> 1.5 | E9: =1 -> 1 | F9: =(D9-0.5)/0.5 -> 2 | G9: =VLOOKUP(A9,Courier_compnay_invoice!B:C,2,0) -> 1.15 | H9: =CEILING(G9,0.5) -> 1.5 | I9: =VLOOKUP(A9,'Company X - Pincode Zones'!A:D,4,0) -> b | J9: =VLOOKUP(I9,'Company X - Pincode Zones'!D:E,2,0) -> Forward charges | K9: =IF(AND(I9="d",J9="Forward charges"),"fwd_d","NA") -> NA | L9: =VLOOKUP(A9,Courier_compnay_invoice!B:F,5,0) -> b | M9: =IFS(I9="a",(Curioer_Rate!$B$5+((D9-0.5)*2)*Curioer_Rate!$C$5), I9 ="b",(Curioer_Rate!$B$6+((D9-0.5)*2)*Curioer_Rate!$C$6), I9="c",(Curioer_Rate!$B$7+((D9-0.5)*2)*Curioer_Rate!$C$7), I9="d",(Curioer_Rate!$B$8+((D9-0.5)*2)*Curioer_Rate!$C$8), I9="e",(Curioer_Rate!$B$9+((D9-0.5)*2)*Curioer_Rate!$C$9)) -> 89.6 | N9: =VLOOKUP(A9,Courier_compnay_invoice!B:H,7,0) -> 89.6 | O9: =M9-N9 -> 0
A10: 2001807186 | B10: 1091117323812 | C10: =SUMIF('Company X - order Report'!$A:$A,A10,'Company X - order Report'!$E:$E) -> 0.5 | D10: =CEILING(C10,0.5) -> 0.5 | E10: =1 -> 1 | F10: =(D10-0.5)/0.5 -> 0 | G10: =VLOOKUP(A10,Courier_compnay_invoice!B:C,2,0) -> 0.5 | H10: =CEILING(G10,0.5) -> 0.5 | I10: =VLOOKUP(A10,'Company X - Pincode Zones'!A:D,4,0) -> d | J10: =VLOOKUP(I10,'Company X - Pincode Zones'!D:E,2,0) -> Forward charges | K10: =IF(AND(I10="d",J10="Forward charges"),"fwd_d","NA") -> fwd_d | L10: =VLOOKUP(A10,Courier_compnay_invoice!B:F,5,0) -> d | M10: =IFS(I10="a",(Curioer_Rate!$B$5+((D10-0.5)*2)*Curioer_Rate!$C$5), I10 ="b",(Curioer_Rate!$B$6+((D10-0.5)*2)*Curioer_Rate!$C$6), I10="c",(Curioer_Rate!$B$7+((D10-0.5)*2)*Curioer_Rate!$C$7), I10="d",(Curioer_Rate!$B$8+((D10-0.5)*2)*Curioer_Rate!$C$8), I10="e",(Curioer_Rate!$B$9+((D10-0.5)*2)*Curioer_Rate!$C$9)) -> 45.4 | N10: =VLOOKUP(A10,Courier_compnay_invoice!B:H,7,0) -> 45.4 | O10: =M10-N10 -> 0
A11: 2001807290 | B11: 1091117324206 | C11: =SUMIF('Company X - order Report'!$A:$A,A11,'Company X - order Report'!$E:$E) -> 0.5 | D11: =CEILING(C11,0.5) -> 0.5 | E11: =1 -> 1 | F11: =(D11-0.5)/0.5 -> 0 | G11: =VLOOKUP(A11,Courier_compnay_invoice!B:C,2,0) -> 0.5 | H11: =CEILING(G11,0.5) -> 0.5 | I11: =VLOOKUP(A11,'Company X - Pincode Zones'!A:D,4,0) -> d | J11: =VLOOKUP(I11,'Company X - Pincode Zones'!D:E,2,0) -> Forward charges | K11: =IF(AND(I11="d",J11="Forward charges"),"fwd_d","NA") -> fwd_d | L11: =VLOOKUP(A11,Courier_compnay_invoice!B:F,5,0) -> d | M11: =IFS(I11="a",(Curioer_Rate!$B$5+((D11-0.5)*2)*Curioer_Rate!$C$5), I11 ="b",(Curioer_Rate!$B$6+((D11-0.5)*2)*Curioer_Rate!$C$6), I11="c",(Curioer_Rate!$B$7+((D11-0.5)*2)*Curioer_Rate!$C$7), I11="d",(Curioer_Rate!$B$8+((D11-0.5)*2)*Curioer_Rate!$C$8), I11="e",(Curioer_Rate!$B$9+((D11-0.5)*2)*Curioer_Rate!$C$9)) -> 45.4 | N11: =VLOOKUP(A11,Courier_compnay_invoice!B:H,7,0) -> 45.4 | O11: =M11-N11 -> 0
A12: 2001807814 | B12: 1091117326612 | C12: =SUMIF('Company X - order Report'!$A:$A,A12,'Company X - order Report'!$E:$E) -> 0.607 | D12: =CEILING(C12,0.5) -> 1 | E12: =1 -> 1 | F12: =(D12-0.5)/0.5 -> 1 | G12: =VLOOKUP(A12,Courier_compnay_invoice!B:C,2,0) -> 0.79 | H12: =CEILING(G12,0.5) -> 1 | I12: =VLOOKUP(A12,'Company X - Pincode Zones'!A:D,4,0) -> b | J12: =VLOOKUP(I12,'Company X - Pincode Zones'!D:E,2,0) -> Forward charges | K12: =IF(AND(I12="d",J12="Forward charges"),"fwd_d","NA") -> NA | L12: =VLOOKUP(A12,Courier_compnay_invoice!B:F,5,0) -> b | M12: =IFS(I12="a",(Curioer_Rate!$B$5+((D12-0.5)*2)*Curioer_Rate!$C$5), I12 ="b",(Curioer_Rate!$B$6+((D12-0.5)*2)*Curioer_Rate!$C$6), I12="c",(Curioer_Rate!$B$7+((D12-0.5)*2)*Curioer_Rate!$C$7), I12="d",(Curioer_Rate!$B$8+((D12-0.5)*2)*Curioer_Rate!$C$8), I12="e",(Curioer_Rate!$B$9+((D12-0.5)*2)*Curioer_Rate!$C$9)) -> 61.3 | N12: =VLOOKUP(A12,Courier_compnay_invoice!B:H,7,0) -> 61.3 | O12: =M12-N12 -> 0
A13: 2001807931 | B13: 1091117327172 | C13: =SUMIF('Company X - order Report'!$A:$A,A13,'Company X - order Report'!$E:$E) -> 0.607 | D13: =CEILING(C13,0.5) -> 1 | E13: =1 -> 1 | F13: =(D13-0.5)/0.5 -> 1 | G13: =VLOOKUP(A13,Courier_compnay_invoice!B:C,2,0) -> 0.72 | H13: =CEILING(G13,0.5) -> 1 | I13: =VLOOKUP(A13,'Company X - Pincode Zones'!A:D,4,0) -> d | J13: =VLOOKUP(I13,'Company X - Pincode Zones'!D:E,2,0) -> Forward charges | K13: =IF(AND(I13="d",J13="Forward charges"),"fwd_d","NA") -> fwd_d | L13: =VLOOKUP(A13,Courier_compnay_invoice!B:F,5,0) -> d | M13: =IFS(I13="a",(Curioer_Rate!$B$5+((D13-0.5)*2)*Curioer_Rate!$C$5), I13 ="b",(Curioer_Rate!$B$6+((D13-0.5)*2)*Curioer_Rate!$C$6), I13="c",(Curioer_Rate!$B$7+((D13-0.5)*2)*Curioer_Rate!$C$7), I13="d",(Curioer_Rate!$B$8+((D13-0.5)*2)*Curioer_Rate!$C$8), I13="e",(Curioer_Rate!$B$9+((D13-0.5)*2)*Curioer_Rate!$C$9)) -> 90.2 | N13: =VLOOKUP(A13,Courier_compnay_invoice!B:H,7,0) -> 90.2 | O13: =M13-N13 -> 0
A14: 2001807956 | B14: 1091117327275 | C14: =SUMIF('Company X - order Report'!$A:$A,A14,'Company X - order Report'!$E:$E) -> 1.08 | D14: =CEILING(C14,0.5) -> 1.5 | E14: =1 -> 1 | F14: =(D14-0.5)/0.5 -> 2 | G14: =VLOOKUP(A14,Courier_compnay_invoice!B:C,2,0) -> 1.08 | H14: =CEILING(G14,0.5) -> 1.5 | I14: =VLOOKUP(A14,'Company X - Pincode Zones'!A:D,4,0) -> b | J14: =VLOOKUP(I14,'Company X - Pincode Zones'!D:E,2,0) -> Forward charges | K14: =IF(AND(I14="d",J14="Forward charges"),"fwd_d","NA") -> NA | L14: =VLOOKUP(A14,Courier_compnay_invoice!B:F,5,0) -> b | M14: =IFS(I14="a",(Curioer_Rate!$B$5+((D14-0.5)*2)*Curioer_Rate!$C$5), I14 ="b",(Curioer_Rate!$B$6+((D14-0.5)*2)*Curioer_Rate!$C$6), I14="c",(Curioer_Rate!$B$7+((D14-0.5)*2)*Curioer_Rate!$C$7), I14="d",(Curioer_Rate!$B$8+((D14-0.5)*2)*Curioer_Rate!$C$8), I14="e",(Curioer_Rate!$B$9+((D14-0.5)*2)*Curioer_Rate!$C$9)) -> 89.6 | N14: =VLOOKUP(A14,Courier_compnay_invoice!B:H,7,0) -> 89.6 | O14: =M14-N14 -> 0
... A125: 2001811305 | B125: 1091121846136 | C125: =SUMIF('Company X - order Report'!$A:$A,A125,'Company X - order Report'!$E:$E) -> 0.75 | D125: =CEILING(C125,0.5) -> 1 | E125: =1 -> 1 | F125: =(D125-0.5)/0.5 -> 1 | G125: =VLOOKUP(A125,Courier_compnay_invoice!B:C,2,0) -> 0.5 | H125: =CEILING(G125,0.5) -> 0.5 | I125: =VLOOKUP(A125,'Company X - Pincode Zones'!A:D,4,0) -> b | J125: =VLOOKUP(I125,'Company X - Pincode Zones'!D:E,2,0) -> Forward charges | K125: =IF(AND(I125="d",J125="Forward charges"),"fwd_d","NA") -> NA | L125: =VLOOKUP(A125,Courier_compnay_invoice!B:F,5,0) -> d | M125: =IFS(I125="a",(Curioer_Rate!$B$5+((D125-0.5)*2)*Curioer_Rate!$C$5), I125 ="b",(Curioer_Rate!$B$6+((D125-0.5)*2)*Curioer_Rate!$C$6), I125="c",(Curioer_Rate!$B$7+((D125-0.5)*2)*Curioer_Rate!$C$7), I125="d",(Curioer_Rate!$B$8+((D125-0.5)*2)*Curioer_Rate!$C$8), I125="e",(Curioer_Rate!$B$9+((D125-0.5)*2)*Curioer_Rate!$C$9)) -> 61.3 | N125: =VLOOKUP(A125,Courier_compnay_invoice!B:H,7,0) -> 45.4 | O125: =M125-N125 -> 15.9

Sheet Summary
B1: Count | C1: Amount(Rs)
A2: Total orders where X has been correctly charged | B2: =COUNTIF(Order_level_Calculation!O:O,"=0") -> 16 | C2: =SUMIF(Order_level_Calculation!O:O,"=0",Order_level_Calculation!O:O) -> 0
A3: Total orders where X has been overchraged | B3: =COUNTIF(Order_level_Calculation!$O:$O,"<0") -> 97 | C3: =SUMIF(Order_level_Calculation!O:O,"<0",Order_level_Calculation!O:O) -> -5573.6
A4: Total orders where X has been undercharged | B4: =COUNTIF(Order_level_Calculation!O:O,">0") -> 11 | C4: =SUMIF(Order_level_Calculation!O:O,">0",Order_level_Calculation!O:O) -> 481.5

Sheet Curioer_Rate
A1: fwd_a_fixed | B1: fwd_a_additional | C1: fwd_b_fixed | D1: fwd_b_additional | E1: fwd_c_fixed | F1: fwd_c_additional | G1: fwd_d_fixed | H1: fwd_d_additional | I1: fwd_e_fixed | J1: fwd_e_additional | K1: rto_a_fixed | L1: rto_a_additional | M1: rto_b_fixed | N1: rto_b_additional | O1: rto_c_fixed | P1: rto_c_additional | Q1: rto_d_fixed | R1: rto_d_additional | S1: rto_e_fixed | T1: rto_e_additional
A2: 29.5 | B2: 23.6 | C2: 33 | D2: 28.3 | E2: 40.1 | F2: 38.9 | G2: 45.4 | H2: 44.8 | I2: 56.6 | J2: 55.5 | K2: 13.6 | L2: 23.6 | M2: 20.5 | N2: 28.3 | O2: 31.9 | P2: 38.9 | Q2: 41.3 | R2: 44.8 | S2: 50.7 | T2: 55.5
A4: Zone | B4: fwd_Fixed | C4: fwd_Additional | D4: Rto_Fixed | E4: Rto_additional
A5: a | B5: 29.5 | C5: 23.6 | D5: 13.6 | E5: 23.6
A6: b | B6: 33 | C6: 28.3 | D6: 20.5 | E6: 28.3
A7: c | B7: 40.1 | C7: 38.9 | D7: 31.9 | E7: 38.9
A8: d | B8: 45.4 | C8: 44.8 | D8: 41.3 | E8: 44.8
A9: e | B9: 56.6 | C9: 55.5 | D9: 50.7 | E9: 55.5

Sheet Courier_compnay_invoice
A1: AWB Code | B1: Order ID | C1: Charged Weight | D1: Warehouse Pincode | E1: Customer Pincode | F1: Zone | G1: Type of Shipment | H1: Billing Amount (Rs.) or Charge Per Shipment
A2: 1091117222124 | B2: 2001806232 | C2: 1.3 | D2: 121003 | E2: 507101 | F2: d | G2: Forward charges | H2: 135
A3: 1091117222194 | B3: 2001806273 | C3: 1 | D3: 121003 | E3: 486886 | F3: d | G3: Forward charges | H3: 90.2
A4: 1091117222931 | B4: 2001806408 | C4: 2.5 | D4: 121003 | E4: 532484 | F4: d | G4: Forward charges | H4: 224.6
A5: 1091117223244 | B5: 2001806458 | C5: 1 | D5: 121003 | E5: 143001 | F5: b | G5: Forward charges | H5: 61.3
A6: 1091117229345 | B6: 2001807012 | C6: 0.15 | D6: 121003 | E6: 515591 | F6: d | G6: Forward charges | H6: 45.4
A7: 1091117229555 | B7: 2001806686 | C7: 0.15 | D7: 121003 | E7: 326502 | F7: d | G7: Forward charges | H7: 45.4
A8: 1091117229776 | B8: 2001806885 | C8: 1 | D8: 121003 | E8: 208019 | F8: b | G8: Forward charges | H8: 61.3
A9: 1091117323112 | B9: 2001807058 | C9: 1.15 | D9: 121003 | E9: 140301 | F9: b | G9: Forward charges | H9: 89.6
A10: 1091117323812 | B10: 2001807186 | C10: 0.5 | D10: 121003 | E10: 396001 | F10: d | G10: Forward charges | H10: 45.4
A11: 1091117324206 | B11: 2001807290 | C11: 0.5 | D11: 121003 | E11: 711106 | F11: d | G11: Forward charges | H11: 45.4
A12: 1091117326612 | B12: 2001807814 | C12: 0.79 | D12: 121003 | E12: 284001 | F12: b | G12: Forward charges | H12: 61.3
A13: 1091117327172 | B13: 2001807931 | C13: 0.72 | D13: 121003 | E13: 441601 | F13: d | G13: Forward charges | H13: 90.2
... A125: 1091121846136 | B125: 2001811305 | C125: 0.5 | D125: 121003 | E125: 302020 | F125: d | G125: Forward charges | H125: 45.4

Sheet Company X - Pincode Zones
A1: Order ID | B1: Warehouse Pincode | C1: Customer Pincode | D1: Zone | E1: Types of Shipment | F1: Rate
A2: 2001806232 | B2: 121003 | C2: 507101 | D2: d | E2: =VLOOKUP(D2,Courier_compnay_invoice!$F:$G,2,0) -> Forward charges
A3: 2001806273 | B3: 121003 | C3: 486886 | D3: d | E3: =VLOOKUP(D3,Courier_compnay_invoice!$F:$G,2,0) -> Forward charges
A4: 2001806408 | B4: 121003 | C4: 532484 | D4: d | E4: =VLOOKUP(D4,Courier_compnay_invoice!$F:$G,2,0) -> Forward charges
A5: 2001806458 | B5: 121003 | C5: 143001 | D5: b | E5: =VLOOKUP(D5,Courier_compnay_invoice!$F:$G,2,0) -> Forward charges
A6: 2001807012 | B6: 121003 | C6: 515591 | D6: d | E6: =VLOOKUP(D6,Courier_compnay_invoice!$F:$G,2,0) -> Forward charges
A7: 2001806686 | B7: 121003 | C7: 326502 | D7: d | E7: =VLOOKUP(D7,Courier_compnay_invoice!$F:$G,2,0) -> Forward charges
A8: 2001806885 | B8: 121003 | C8: 208019 | D8: b | E8: =VLOOKUP(D8,Courier_compnay_invoice!$F:$G,2,0) -> Forward charges
A9: 2001807058 | B9: 121003 | C9: 140301 | D9: b | E9: =VLOOKUP(D9,Courier_compnay_invoice!$F:$G,2,0) -> Forward charges
A10: 2001807186 | B10: 121003 | C10: 396001 | D10: d | E10: =VLOOKUP(D10,Courier_compnay_invoice!$F:$G,2,0) -> Forward charges
A11: 2001807290 | B11: 121003 | C11: 711106 | D11: d | E11: =VLOOKUP(D11,Courier_compnay_invoice!$F:$G,2,0) -> Forward charges
A12: 2001807814 | B12: 121003 | C12: 284001 | D12: b | E12: =VLOOKUP(D12,Courier_compnay_invoice!$F:$G,2,0) -> Forward charges
A13: 2001807931 | B13: 121003 | C13: 441601 | D13: d | E13: =VLOOKUP(D13,Courier_compnay_invoice!$F:$G,2,0) -> Forward charges
... A125: 2001811305 | B125: 121003 | C125: 302020 | D125: b | E125: =VLOOKUP(D125,Courier_compnay_invoice!$F:$G,2,0) -> Forward charges

Sheet Company X - order Report
A1: Order ID | B1: SKU | C1: Order Qty | D1: Weight(g) | E1: weight (kg)
A2: 2001827036 | B2: 8904223818706 | C2: 1.00 | D2: =VLOOKUP(B2,'Company X - SKU Master'!$A:$B,2,0) -> 127 | E2: =(C2*D2)/1000 -> 0.127
A3: 2001827036 | B3: 8904223819093 | C3: 1.00 | D3: =VLOOKUP(B3,'Company X - SKU Master'!$A:$B,2,0) -> 150 | E3: =(C3*D3)/1000 -> 0.15
A4: 2001827036 | B4: 8904223819109 | C4: 1.00 | D4: =VLOOKUP(B4,'Company X - SKU Master'!$A:$B,2,0) -> 100 | E4: =(C4*D4)/1000 -> 0.1
A5: 2001827036 | B5: 8904223818430 | C5: 1.00 | D5: =VLOOKUP(B5,'Company X - SKU Master'!$A:$B,2,0) -> 165 | E5: =(C5*D5)/1000 -> 0.165
A6: 2001827036 | B6: 8904223819277 | C6: 1.00 | D6: =VLOOKUP(B6,'Company X - SKU Master'!$A:$B,2,0) -> 350 | E6: =(C6*D6)/1000 -> 0.35
A7: 2001827036 | B7: GIFTBOX202002 | C7: 1.00 | D7: =VLOOKUP(B7,'Company X - SKU Master'!$A:$B,2,0) -> 500 | E7: =(C7*D7)/1000 -> 0.5
A8: 2001827036 | B8: 8904223818638 | C8: 2.00 | D8: =VLOOKUP(B8,'Company X - SKU Master'!$A:$B,2,0) -> 137 | E8: =(C8*D8)/1000 -> 0.274
A9: 2001827036 | B9: SACHETS001 | C9: 1.00 | D9: =VLOOKUP(B9,'Company X - SKU Master'!$A:$B,2,0) -> 10 | E9: =(C9*D9)/1000 -> 0.01
A10: 2001825261 | B10: 8904223819024 | C10: 4.00 | D10: =VLOOKUP(B10,'Company X - SKU Master'!$A:$B,2,0) -> 112 | E10: =(C10*D10)/1000 -> 0.448
A11: 2001825261 | B11: 8904223819291 | C11: 4.00 | D11: =VLOOKUP(B11,'Company X - SKU Master'!$A:$B,2,0) -> 112 | E11: =(C11*D11)/1000 -> 0.448
A12: 2001825261 | B12: 8904223818638 | C12: 3.00 | D12: =VLOOKUP(B12,'Company X - SKU Master'!$A:$B,2,0) -> 137 | E12: =(C12*D12)/1000 -> 0.411
A13: 2001825261 | B13: 8904223818669 | C13: 1.00 | D13: =VLOOKUP(B13,'Company X - SKU Master'!$A:$B,2,0) -> 240 | E13: =(C13*D13)/1000 -> 0.24
A14: 2001825261 | B14: SACHETS001 | C14: 1.00 | D14: =VLOOKUP(B14,'Company X - SKU Master'!$A:$B,2,0) -> 10 | E14: =(C14*D14)/1000 -> 0.01
A15: 2001823564 | B15: 8904223819291 | C15: 2.00 | D15: =VLOOKUP(B15,'Company X - SKU Master'!$A:$B,2,0) -> 112 | E15: =(C15*D15)/1000 -> 0.224
A16: 2001823564 | B16: 8904223819031 | C16: 2.00 | D16: =VLOOKUP(B16,'Company X - SKU Master'!$A:$B,2,0) -> 112 | E16: =(C16*D16)/1000 -> 0.224
A17: 2001823564 | B17: 8904223819024 | C17: 2.00 | D17: =VLOOKUP(B17,'Company X - SKU Master'!$A:$B,2,0) -> 112 | E17: =(C17*D17)/1000 -> 0.224
A18: 2001822466 | B18: 8904223819468 | C18: 2.00 | D18: =VLOOKUP(B18,'Company X - SKU Master'!$A:$B,2,0) -> 240 | E18: =(C18*D18)/1000 -> 0.48
A19: 2001822466 | B19: 8904223819291 | C19: 8.00 | D19: =VLOOKUP(B19,'Company X - SKU Master'!$A:$B,2,0) -> 112 | E19: =(C19*D19)/1000 -> 0.896
A20: 2001821995 | B20: 8904223819130 | C20: 1.00 | D20: =VLOOKUP(B20,'Company X - SKU Master'!$A:$B,2,0) -> 350 | E20: =(C20*D20)/1000 -> 0.35
A21: 2001821995 | B21: 8904223818706 | C21: 1.00 | D21: =VLOOKUP(B21,'Company X - SKU Master'!$A:$B,2,0) -> 127 | E21: =(C21*D21)/1000 -> 0.127
A22: 2001821766 | B22: 8904223818591 | C22: 2.00 | D22: =VLOOKUP(B22,'Company X - SKU Master'!$A:$B,2,0) -> 120 | E22: =(C22*D22)/1000 -> 0.24
A23: 2001821750 | B23: 8904223818850 | C23: 1.00 | D23: =VLOOKUP(B23,'Company X - SKU Master'!$A:$B,2,0) -> 240 | E23: =(C23*D23)/1000 -> 0.24
A24: 2001821750 | B24: 8904223818430 | C24: 1.00 | D24: =VLOOKUP(B24,'Company X - SKU Master'!$A:$B,2,0) -> 165 | E24: =(C24*D24)/1000 -> 0.165
A25: 2001821750 | B25: 8904223819130 | C25: 1.00 | D25: =VLOOKUP(B25,'Company X - SKU Master'!$A:$B,2,0) -> 350 | E25: =(C25*D25)/1000 -> 0.35
A26: 2001821742 | B26: 8904223819468 | C26: 1.00 | D26: =VLOOKUP(B26,'Company X - SKU Master'!$A:$B,2,0) -> 240 | E26: =(C26*D26)/1000 -> 0.24
... A47: 2001819252 | B47: 8904223818706 | C47: 1.00 | D47: =VLOOKUP(B47,'Company X - SKU Master'!$A:$B,2,0) -> 127 | E47: =(C47*D47)/1000 -> 0.127
A48: 2001819252 | B48: SACHETS001 | C48: 1.00 | D48: =VLOOKUP(B48,'Company X - SKU Master'!$A:$B,2,0) -> 10 | E48: =(C48*D48)/1000 -> 0.01
A49: 2001818390 | B49: 8904223819147 | C49: 1.00 | D49: =VLOOKUP(B49,'Company X - SKU Master'!$A:$B,2,0) -> 240 | E49: =(C49*D49)/1000 -> 0.24
A50: 2001818390 | B50: 8904223818935 | C50: 4.00 | D50: =VLOOKUP(B50,'Company X - SKU Master'!$A:$B,2,0) -> 120 | E50: =(C50*D50)/1000 -> 0.48
A51: 2001818390 | B51: 8904223818683 | C51: 1.00 | D51: =VLOOKUP(B51,'Company X - SKU Master'!$A:$B,2,0) -> 121 | E51: =(C51*D51)/1000 -> 0.121
A52: 2001817160 | B52: 8904223818478 | C52: 1.00 | D52: =VLOOKUP(B52,'Company X - SKU Master'!$A:$B,2,0) -> 350 | E52: =(C52*D52)/1000 -> 0.35
A53: 2001817160 | B53: 8904223819284 | C53: 1.00 | D53: =VLOOKUP(B53,'Company X - SKU Master'!$A:$B,2,0) -> 350 | E53: =(C53*D53)/1000 -> 0.35
A54: 2001817093 | B54: 8904223816214 | C54: 1.00 | D54: =VLOOKUP(B54,'Company X - SKU Master'!$A:$B,2,0) -> 120 | E54: =(C54*D54)/1000 -> 0.12
A55: 2001817093 | B55: 8904223818874 | C55: 1.00 | D55: =VLOOKUP(B55,'Company X - SKU Master'!$A:$B,2,0) -> 100 | E55: =(C55*D55)/1000 -> 0.1
A56: 2001817093 | B56: 8904223819512 | C56: 1.00 | D56: =VLOOKUP(B56,'Company X - SKU Master'!$A:$B,2,0) -> 210 | E56: =(C56*D56)/1000 -> 0.21
A57: 2001817093 | B57: 8904223818881 | C57: 1.00 | D57: =VLOOKUP(B57,'Company X - SKU Master'!$A:$B,2,0) -> 140 | E57: =(C57*D57)/1000 -> 0.14
A58: 2001817093 | B58: 8904223819291 | C58: 2.00 | D58: =VLOOKUP(B58,'Company X - SKU Master'!$A:$B,2,0) -> 112 | E58: =(C58*D58)/1000 -> 0.224
A59: 2001817093 | B59: 8904223819031 | C59: 2.00 | D59: =VLOOKUP(B59,'Company X - SKU Master'!$A:$B,2,0) -> 112 | E59: =(C59*D59)/1000 -> 0.224
A60: 2001817093 | B60: 8904223819024 | C60: 2.00 | D60: =VLOOKUP(B60,'Company X - SKU Master'!$A:$B,2,0) -> 112 | E60: =(C60*D60)/1000 -> 0.224
...

Sheet Company X - SKU Master
A1: SKU | B1: Weight (g)
A2: 8904223815682 | B2: 210
A3: 8904223815859 | B3: 165
A4: 8904223815866 | B4: 113
A5: 8904223815873 | B5: 65
A6: 8904223816214 | B6: 120
A7: 8904223816665 | B7: 102
A8: 8904223817273 | B8: 65
A9: 8904223817334 | B9: 170
A10: 8904223817501 | B10: 350
A11: 8904223818430 | B11: 165
A12: 8904223818478 | B12: 350
A13: 8904223818553 | B13: 115
... A51: 8904223819437 | B51: 552
A52: GIFTBOX202001 | B52: 500
A53: GIFTBOX202004 | B53: 500
A54: GIFTBOX202002 | B54: 500
A55: 8904223819369 | B55: 170
A56: GIFTBOX202003 | B56: 500
A57: 8904223819123 | B57: 250
A58: GIFTBOX202002 | B58: 500
A59: 8904223819468 | B59: 240
A60: 8904223819260 | B60: 130
A61: 8904223819321 | B61: 600
A62: 8904223819338 | B62: 600
A63: 8904223819505 | B63: 210
A64: 8904223819499 | B64: 210
A65: 8904223819512 | B65: 210
A66: 8904223819543 | B66: 300
A67: SACHETS001 | B67: 10
